2023-03-03 09:56:07.356|INFO|Received user info from Google {'iss': 'https://accounts.google.com', 'azp': '228981541877-eu1up7ttd5f96e14qm95963klt8185j9.apps.googleusercontent.com', 'aud': '228981541877-eu1up7ttd5f96e14qm95963klt8185j9.apps.googleusercontent.com', 'sub': '104975551021591622453', 'email': 'phucld.dev@gmail.com', 'email_verified': 'true', 'at_hash': 'e5TK6pQ1ld4-T3rqadlJCw', 'name': 'Phuc Luu', 'picture': 'https://lh3.googleusercontent.com/a/AGNmyxYAkgWgkS-LvgqqvSR0Fv0dklhzlaWml6YahtzR=s96-c', 'given_name': 'Phuc', 'family_name': 'Luu', 'locale': 'vi', 'iat': '1677837367', 'exp': '1677840967', 'alg': 'RS256', 'kid': '255cca6ec2810602d80bec89e456c4495d7418bb', 'typ': 'JWT'}, code: 4/0AWtgzh6DUvGKYoEpLljFM4QXN2Voo-LDPRnkwqKWkGjANds_QiUhOkh1XJHgxraMkCHP9A
2023-03-03 09:56:07.358|ERROR|google_oauth2_callback_exception
Traceback (most recent call last):
  File "/usr/local/Cellar/python/3.7.2_2/Frameworks/Python.framework/Versions/3.7/lib/python3.7/threading.py", line 885, in _bootstrap
    self._bootstrap_inner()
  File "/usr/local/Cellar/python/3.7.2_2/Frameworks/Python.framework/Versions/3.7/lib/python3.7/threading.py", line 917, in _bootstrap_inner
    self.run()
  File "/usr/local/Cellar/python/3.7.2_2/Frameworks/Python.framework/Versions/3.7/lib/python3.7/threading.py", line 865, in run
    self._target(*self._args, **self._kwargs)
  File "/usr/local/Cellar/python/3.7.2_2/Frameworks/Python.framework/Versions/3.7/lib/python3.7/concurrent/futures/thread.py", line 80, in _worker
    work_item.run()
  File "/usr/local/Cellar/python/3.7.2_2/Frameworks/Python.framework/Versions/3.7/lib/python3.7/concurrent/futures/thread.py", line 57, in run
    result = self.fn(*self.args, **self.kwargs)
  File "/Users/phucluu/Documents/GitHub/django-money-keeper-api/venv/lib/python3.7/site-packages/asgiref/sync.py", line 248, in _run_event_loop
    loop.run_until_complete(coro)
  File "/usr/local/Cellar/python/3.7.2_2/Frameworks/Python.framework/Versions/3.7/lib/python3.7/asyncio/base_events.py", line 571, in run_until_complete
    self.run_forever()
  File "/usr/local/Cellar/python/3.7.2_2/Frameworks/Python.framework/Versions/3.7/lib/python3.7/asyncio/base_events.py", line 539, in run_forever
    self._run_once()
  File "/usr/local/Cellar/python/3.7.2_2/Frameworks/Python.framework/Versions/3.7/lib/python3.7/asyncio/base_events.py", line 1775, in _run_once
    handle._run()
  File "/usr/local/Cellar/python/3.7.2_2/Frameworks/Python.framework/Versions/3.7/lib/python3.7/asyncio/events.py", line 88, in _run
    self._context.run(self._callback, *self._args)
  File "/Users/phucluu/Documents/GitHub/django-money-keeper-api/common/decorator.py", line 73, in _func
    log.exception('%s_exception', func.__name__)
  File "/Users/phucluu/Documents/GitHub/django-money-keeper-api/common/decorator.py", line 67, in _func
    response = await func(request, *args, **kwargs)
  File "/Users/phucluu/Documents/GitHub/django-money-keeper-api/venv/lib/python3.7/site-packages/asgiref/sync.py", line 448, in __call__
    ret = await asyncio.wait_for(future, timeout=None)
  File "/usr/local/Cellar/python/3.7.2_2/Frameworks/Python.framework/Versions/3.7/lib/python3.7/asyncio/tasks.py", line 388, in wait_for
    return await fut
  File "/Users/phucluu/Documents/GitHub/django-money-keeper-api/venv/lib/python3.7/site-packages/asgiref/current_thread_executor.py", line 22, in run
    result = self.fn(*self.args, **self.kwargs)
  File "/Users/phucluu/Documents/GitHub/django-money-keeper-api/venv/lib/python3.7/site-packages/asgiref/sync.py", line 490, in thread_handler
    return func(*args, **kwargs)
  File "/Users/phucluu/Documents/GitHub/django-money-keeper-api/api/users.py", line 55, in google_oauth2_callback
    user = User.objects.get(username=email)
  File "/Users/phucluu/Documents/GitHub/django-money-keeper-api/venv/lib/python3.7/site-packages/django/db/models/manager.py", line 190, in __get__
    cls._meta.swapped,
AttributeError: Manager isn't available; 'auth.User' has been swapped for 'services.User'

2023-03-03 09:58:49.881|ERROR|Cannot get token from code: 4/0AWtgzh6DUvGKYoEpLljFM4QXN2Voo-LDPRnkwqKWkGjANds_QiUhOkh1XJHgxraMkCHP9A, {'error': 'invalid_grant', 'error_description': 'Bad Request'}
2023-03-03 09:58:49.881|INFO|Received user info from Google {}, code: 4/0AWtgzh6DUvGKYoEpLljFM4QXN2Voo-LDPRnkwqKWkGjANds_QiUhOkh1XJHgxraMkCHP9A
2023-03-03 09:58:49.881|ERROR|Cannot get user info from token. Received data from Google {}
2023-03-03 10:02:17.203|INFO|Received user info from Google {'iss': 'https://accounts.google.com', 'azp': '228981541877-eu1up7ttd5f96e14qm95963klt8185j9.apps.googleusercontent.com', 'aud': '228981541877-eu1up7ttd5f96e14qm95963klt8185j9.apps.googleusercontent.com', 'sub': '104975551021591622453', 'email': 'phucld.dev@gmail.com', 'email_verified': 'true', 'at_hash': '6mE8eh3hxUz8xHexf17EjA', 'name': 'Phuc Luu', 'picture': 'https://lh3.googleusercontent.com/a/AGNmyxYAkgWgkS-LvgqqvSR0Fv0dklhzlaWml6YahtzR=s96-c', 'given_name': 'Phuc', 'family_name': 'Luu', 'locale': 'vi', 'iat': '1677837737', 'exp': '1677841337', 'alg': 'RS256', 'kid': '255cca6ec2810602d80bec89e456c4495d7418bb', 'typ': 'JWT'}, code: 4/0AWtgzh4yeHYEsh0yfNgEmypi1pwPXMxVBQ5RBm2x5v0EYSMji9msL9GAj9S-qOUpSuqBiA
2023-03-03 10:04:40.531|ERROR|Cannot get token from code: 4/0AWtgzh4yeHYEsh0yfNgEmypi1pwPXMxVBQ5RBm2x5v0EYSMji9msL9GAj9S-qOUpSuqBiA, {'error': 'invalid_grant', 'error_description': 'Bad Request'}
2023-03-03 10:04:40.531|INFO|Received user info from Google {}, code: 4/0AWtgzh4yeHYEsh0yfNgEmypi1pwPXMxVBQ5RBm2x5v0EYSMji9msL9GAj9S-qOUpSuqBiA
2023-03-03 10:04:40.531|ERROR|Cannot get user info from token. Received data from Google {}
2023-03-03 10:07:15.646|INFO|Received user info from Google {'iss': 'https://accounts.google.com', 'azp': '228981541877-eu1up7ttd5f96e14qm95963klt8185j9.apps.googleusercontent.com', 'aud': '228981541877-eu1up7ttd5f96e14qm95963klt8185j9.apps.googleusercontent.com', 'sub': '104975551021591622453', 'email': 'phucld.dev@gmail.com', 'email_verified': 'true', 'at_hash': 'jkx4cqwgjNhEWMnt9vTExg', 'name': 'Phuc Luu', 'picture': 'https://lh3.googleusercontent.com/a/AGNmyxYAkgWgkS-LvgqqvSR0Fv0dklhzlaWml6YahtzR=s96-c', 'given_name': 'Phuc', 'family_name': 'Luu', 'locale': 'vi', 'iat': '1677838035', 'exp': '1677841635', 'alg': 'RS256', 'kid': '255cca6ec2810602d80bec89e456c4495d7418bb', 'typ': 'JWT'}, code: 4/0AWtgzh49BRtTj-l6mBikYM1Ee2jssg0gIuW7D-MTYHAjNQKZiTZW_YVC7qk0ysndkfUFYw
2023-03-03 10:08:37.940|ERROR|Cannot get token from code: 4/0AWtgzh49BRtTj-l6mBikYM1Ee2jssg0gIuW7D-MTYHAjNQKZiTZW_YVC7qk0ysndkfUFYw, {'error': 'invalid_grant', 'error_description': 'Bad Request'}
2023-03-03 10:08:37.941|INFO|Received user info from Google {}, code: 4/0AWtgzh49BRtTj-l6mBikYM1Ee2jssg0gIuW7D-MTYHAjNQKZiTZW_YVC7qk0ysndkfUFYw
2023-03-03 10:08:37.941|ERROR|Cannot get user info from token. Received data from Google {}
2023-03-03 10:09:31.264|INFO|Received user info from Google {'iss': 'https://accounts.google.com', 'azp': '228981541877-eu1up7ttd5f96e14qm95963klt8185j9.apps.googleusercontent.com', 'aud': '228981541877-eu1up7ttd5f96e14qm95963klt8185j9.apps.googleusercontent.com', 'sub': '104975551021591622453', 'email': 'phucld.dev@gmail.com', 'email_verified': 'true', 'at_hash': 'ew4Oo0O1g1jgyjBPe9O_rw', 'name': 'Phuc Luu', 'picture': 'https://lh3.googleusercontent.com/a/AGNmyxYAkgWgkS-LvgqqvSR0Fv0dklhzlaWml6YahtzR=s96-c', 'given_name': 'Phuc', 'family_name': 'Luu', 'locale': 'vi', 'iat': '1677838171', 'exp': '1677841771', 'alg': 'RS256', 'kid': '255cca6ec2810602d80bec89e456c4495d7418bb', 'typ': 'JWT'}, code: 4/0AWtgzh6fkuDaNlGpOLiZq8-NLRRvYTJ2rWkBCc8LjfM4-iUSXi1ZKRc0li_pMt7pRwVYTw
2023-03-03 10:09:31.694|INFO|Login successfully. User Id: 2
2023-03-03 10:11:03.308|INFO|Received user info from Google {'iss': 'https://accounts.google.com', 'azp': '228981541877-eu1up7ttd5f96e14qm95963klt8185j9.apps.googleusercontent.com', 'aud': '228981541877-eu1up7ttd5f96e14qm95963klt8185j9.apps.googleusercontent.com', 'sub': '104975551021591622453', 'email': 'phucld.dev@gmail.com', 'email_verified': 'true', 'at_hash': 'uYISjkkeWm3ghtLJncvVMw', 'name': 'Phuc Luu', 'picture': 'https://lh3.googleusercontent.com/a/AGNmyxYAkgWgkS-LvgqqvSR0Fv0dklhzlaWml6YahtzR=s96-c', 'given_name': 'Phuc', 'family_name': 'Luu', 'locale': 'vi', 'iat': '1677838263', 'exp': '1677841863', 'alg': 'RS256', 'kid': '255cca6ec2810602d80bec89e456c4495d7418bb', 'typ': 'JWT'}, code: 4/0AWtgzh4M0XtQryf_A-4Rg48Dmd-X8jyE1CUxSaZ-RdrlSuW2n3kVe_-l_QV3vaFMhvhfAw
2023-03-03 10:11:03.309|ERROR|google_oauth2_callback_exception
Traceback (most recent call last):
  File "/usr/local/Cellar/python/3.7.2_2/Frameworks/Python.framework/Versions/3.7/lib/python3.7/threading.py", line 885, in _bootstrap
    self._bootstrap_inner()
  File "/usr/local/Cellar/python/3.7.2_2/Frameworks/Python.framework/Versions/3.7/lib/python3.7/threading.py", line 917, in _bootstrap_inner
    self.run()
  File "/usr/local/Cellar/python/3.7.2_2/Frameworks/Python.framework/Versions/3.7/lib/python3.7/threading.py", line 865, in run
    self._target(*self._args, **self._kwargs)
  File "/usr/local/Cellar/python/3.7.2_2/Frameworks/Python.framework/Versions/3.7/lib/python3.7/concurrent/futures/thread.py", line 80, in _worker
    work_item.run()
  File "/usr/local/Cellar/python/3.7.2_2/Frameworks/Python.framework/Versions/3.7/lib/python3.7/concurrent/futures/thread.py", line 57, in run
    result = self.fn(*self.args, **self.kwargs)
  File "/Users/phucluu/Documents/GitHub/django-money-keeper-api/venv/lib/python3.7/site-packages/asgiref/sync.py", line 248, in _run_event_loop
    loop.run_until_complete(coro)
  File "/usr/local/Cellar/python/3.7.2_2/Frameworks/Python.framework/Versions/3.7/lib/python3.7/asyncio/base_events.py", line 571, in run_until_complete
    self.run_forever()
  File "/usr/local/Cellar/python/3.7.2_2/Frameworks/Python.framework/Versions/3.7/lib/python3.7/asyncio/base_events.py", line 539, in run_forever
    self._run_once()
  File "/usr/local/Cellar/python/3.7.2_2/Frameworks/Python.framework/Versions/3.7/lib/python3.7/asyncio/base_events.py", line 1775, in _run_once
    handle._run()
  File "/usr/local/Cellar/python/3.7.2_2/Frameworks/Python.framework/Versions/3.7/lib/python3.7/asyncio/events.py", line 88, in _run
    self._context.run(self._callback, *self._args)
  File "/Users/phucluu/Documents/GitHub/django-money-keeper-api/venv/lib/python3.7/site-packages/asgiref/sync.py", line 306, in main_wrap
    result = await self.awaitable(*args, **kwargs)
  File "/Users/phucluu/Documents/GitHub/django-money-keeper-api/common/decorator.py", line 73, in _func
    log.exception('%s_exception', func.__name__)
  File "/Users/phucluu/Documents/GitHub/django-money-keeper-api/common/decorator.py", line 69, in _func
    response = func(request, *args, **kwargs)
  File "/Users/phucluu/Documents/GitHub/django-money-keeper-api/api/users.py", line 55, in google_oauth2_callback
    user = User.objects.get(username=email)
  File "/Users/phucluu/Documents/GitHub/django-money-keeper-api/venv/lib/python3.7/site-packages/django/db/models/manager.py", line 85, in manager_method
    return getattr(self.get_queryset(), name)(*args, **kwargs)
  File "/Users/phucluu/Documents/GitHub/django-money-keeper-api/venv/lib/python3.7/site-packages/django/db/models/query.py", line 431, in get
    num = len(clone)
  File "/Users/phucluu/Documents/GitHub/django-money-keeper-api/venv/lib/python3.7/site-packages/django/db/models/query.py", line 262, in __len__
    self._fetch_all()
  File "/Users/phucluu/Documents/GitHub/django-money-keeper-api/venv/lib/python3.7/site-packages/django/db/models/query.py", line 1324, in _fetch_all
    self._result_cache = list(self._iterable_class(self))
  File "/Users/phucluu/Documents/GitHub/django-money-keeper-api/venv/lib/python3.7/site-packages/django/db/models/query.py", line 51, in __iter__
    results = compiler.execute_sql(chunked_fetch=self.chunked_fetch, chunk_size=self.chunk_size)
  File "/Users/phucluu/Documents/GitHub/django-money-keeper-api/venv/lib/python3.7/site-packages/django/db/models/sql/compiler.py", line 1173, in execute_sql
    cursor = self.connection.cursor()
  File "/Users/phucluu/Documents/GitHub/django-money-keeper-api/venv/lib/python3.7/site-packages/django/utils/asyncio.py", line 31, in inner
    raise SynchronousOnlyOperation(message)
django.core.exceptions.SynchronousOnlyOperation: You cannot call this from an async context - use a thread or sync_to_async.

2023-03-03 10:11:35.395|INFO|Received user info from Google {'iss': 'https://accounts.google.com', 'azp': '228981541877-eu1up7ttd5f96e14qm95963klt8185j9.apps.googleusercontent.com', 'aud': '228981541877-eu1up7ttd5f96e14qm95963klt8185j9.apps.googleusercontent.com', 'sub': '104975551021591622453', 'email': 'phucld.dev@gmail.com', 'email_verified': 'true', 'at_hash': 'TRqzBVjz74KQxKoWrUZx2Q', 'name': 'Phuc Luu', 'picture': 'https://lh3.googleusercontent.com/a/AGNmyxYAkgWgkS-LvgqqvSR0Fv0dklhzlaWml6YahtzR=s96-c', 'given_name': 'Phuc', 'family_name': 'Luu', 'locale': 'vi', 'iat': '1677838295', 'exp': '1677841895', 'alg': 'RS256', 'kid': '255cca6ec2810602d80bec89e456c4495d7418bb', 'typ': 'JWT'}, code: 4/0AWtgzh6q7ugsJ1ivZkjh-nkFhubqTdH2_lfSzr28tZT1qVto5wSY7AN3yH0mYDfUgRXz9A
2023-03-03 10:11:35.606|INFO|Login successfully. User Id: 2
2023-03-03 10:18:20.905|INFO|Received user info from Google {'iss': 'https://accounts.google.com', 'azp': '228981541877-eu1up7ttd5f96e14qm95963klt8185j9.apps.googleusercontent.com', 'aud': '228981541877-eu1up7ttd5f96e14qm95963klt8185j9.apps.googleusercontent.com', 'sub': '116891329041053586549', 'email': 'phucluu181@gmail.com', 'email_verified': 'true', 'at_hash': '683GL_Okms8AGIJfaqcy6g', 'name': 'Phuc Luu', 'picture': 'https://lh3.googleusercontent.com/a/AGNmyxb9Jlolwypkwudc7TqC5Ai07ZSAYU69JVAmSDwL=s96-c', 'given_name': 'Phuc', 'family_name': 'Luu', 'locale': 'vi', 'iat': '1677838701', 'exp': '1677842301', 'alg': 'RS256', 'kid': '255cca6ec2810602d80bec89e456c4495d7418bb', 'typ': 'JWT'}, code: 4/0AWtgzh7RsYE0Kh7fMQpU8hhQPmS0OZSXbJBPSC5xRqomlxHVaQBFtDkjLJWlqs2xgKSdGQ
2023-03-03 10:18:21.343|INFO|Login successfully. User Id: 3
